<?xml version="1.0"?>
<robot name="tumble">

  <material name="white">
    <color rgba="1 1 1 1"/>
  </material>

  <material name="black">
    <color rgba="0.2 0.2 0.2 1"/>
  </material>

  <link name="torso">
    <visual>
      <geometry>
        <box size="0.1778 0.1143 0.060321"/>
      </geometry>
      <origin rpy="0 0 0" xyz="0 0.0 0"/>
      <material name="white"/>
    </visual>
    <collision>
      <geometry>
        <box size="0.1778 0.1143 0.060321"/>
      </geometry>
      <origin rpy="0 0 0" xyz="0 0.0 0"/>
    </collision>
    <inertial>
      <mass value="0.55"/>
      <inertia ixx="0.00306223739085" ixy="0.00279434925" ixz="0.0014746976475" iyy="0.00646276822418" iyz="0.00094801991625" izz="0.00819084383333"/>
      <origin rpy="0 0 0" xyz="0 0.0 0"/>
    </inertial>
  </link>

  <link name="l_leg">
    <visual>
      <geometry>
        <box size="0.1516 0.00635 0.009525"/>
      </geometry>
      <origin rpy="0 1.5707963 0" xyz="0 0.02 0.05"/>
      <material name="green"/>
    </visual>
    <collision>
      <geometry>
        <box size="0.1516 0.00635 0.009525"/>
      </geometry>
      <origin rpy="0 1.5707963 0" xyz="0 0.02 0.05"/>
      <contact_coefficients mu="0.8" />
    </collision>
    <inertial>
      <mass value="0.0085"/>
      <inertia ixx="3.71303020833e-07" ixy="2.0456525e-06" ixz="3.06847875e-06" iyy="6.53743092708e-05" iyz="1.2852796875e-07" izz="6.52315004167e-05"/>
      <origin rpy="0 1.5707963 0" xyz="0 0.02 0.05"/>
    </inertial>
  </link>

  <link name="r_leg">
    <visual>
      <geometry>
        <box size="0.1516 0.00635 0.009525"/>
      </geometry>
      <origin rpy="0 1.5707963 0" xyz="0 0.02 0.05"/>
      <material name="black"/>
    </visual>
    <collision>
      <geometry>
        <box size="0.1516 0.00635 0.009525"/>
      </geometry>
      <origin rpy="0 1.5707963 0" xyz="0 0.02 0.05"/>
      <contact_coefficients mu="0.8" />
    </collision>
    <inertial>
      <mass value="0.0085"/>
      <inertia ixx="3.71303020833e-07" ixy="2.0456525e-06" ixz="3.06847875e-06" iyy="6.53743092708e-05" iyz="1.2852796875e-07" izz="6.52315004167e-05"/>
      <origin rpy="0 1.5707963 0" xyz="0 0.02 0.05"/>
    </inertial>
  </link>

  <joint name="torso_l_leg" type="continuous">
    <parent link="torso"/>
    <child link="l_leg"/>
    <axis xyz="-1 0 0"/>
    <limit effort="1000" velocity="100"/>
    <origin rpy="0 0 0" xyz="-0.10795 0.0 0"/>
  </joint>

  <joint name="torso_r_leg" type="continuous">
    <parent link="torso"/>
    <child link="r_leg"/>
    <axis xyz="1 0 0"/>
   <limit effort="1000" velocity="100"/>
   <origin rpy="0 0 0" xyz="0.10795 0.0 0"/>
  </joint>

</robot>