<robot name="tumble">

  <material name="white">
    <color rgba="1 1 1 1" />
  </material>

  <material name="black">
    <color rgba="0.2 0.2 0.2 1" />
  </material>

  <link name="torso">
    <visual>
      <geometry>
        <box size=" 0.19196386542764682 0.15493644869125323 0.0838460706608761" />
      </geometry>
      <origin rpy="0 0 0" xyz="0 0.0 0" />
      <material name="white" />
    </visual>
    <collision>
      <geometry>
        <box size=" 0.19196386542764682 0.15493644869125323 0.0838460706608761" />
      </geometry>
      <origin rpy="0 0 0" xyz="0 0.0 0" />
    </collision>
    <inertial>
      <mass value=" 0.7309474692412153" />
      <inertia ixx="0.01043604723873125" ixy="0.004949522263203204" ixz="0.002201754225910902" iyy="0.005998722953961083" iyz="0.0029721196684499487" izz="0.01467637381334591" />
      <origin rpy="0 0 0" xyz="0 0.0 0" />
    </inertial>
  </link>

  <link name="l_leg">
    <visual>
      <geometry>
        <box size=" 0.12185528088883765 0.0029425462726722605 0.0078069709492131325" />
      </geometry>
      <origin rpy="0 1.5707963 0" xyz="0 0.0 0.064" />
      <material name="green" />
    </visual>
    <collision>
      <geometry>
        <box size=" 0.12185528088883765 0.0029425462726722605 0.0078069709492131325" />
      </geometry>
      <origin rpy="0 1.5707963 0" xyz="0 0.0 0.064" />
      <contact_coefficients mu=" 0.7789371926880387" />
    </collision>
    <inertial>
      <mass value=" 0.00387440059598607" />
      <inertia ixx="2.1694101579309203e-05" ixy="3.8765900275043895e-07" ixz="2.3122531945381576e-08" iyy="1.0690147912909569e-07" iyz="1.146982431932699e-06" izz="2.2548863067431072e-05" />
      <origin rpy="0 1.5707963 0" xyz="0 0.0 0.064" />
    </inertial>
  </link>

  <link name="r_leg">
    <visual>
      <geometry>
        <box size=" 0.1284966631488819 0.0030572590216893605 0.008136040396106669" />
      </geometry>
      <origin rpy="0 1.5707963 0" xyz="0 0.0 0.064" />
      <material name="black" />
    </visual>
    <collision>
      <geometry>
        <box size=" 0.1284966631488819 0.0030572590216893605 0.008136040396106669" />
      </geometry>
      <origin rpy="0 1.5707963 0" xyz="0 0.0 0.064" />
      <contact_coefficients mu=" 0.7956064487635404" />
    </collision>
    <inertial>
      <mass value=" 0.004010956204078163" />
      <inertia ixx="2.183804532144651e-05" ixy="3.6947693401328713e-07" ixz="2.595457813092116e-08" iyy="1.0474434876547154e-07" iyz="1.058116411487207e-06" izz="2.2058313187749295e-05" />
      <origin rpy="0 1.5707963 0" xyz="0 0.0 0.064" />
    </inertial>
  </link>

  <joint name="torso_l_leg" type="continuous">
    <parent link="torso" />
    <child link="l_leg" />
    <axis xyz="-1 0 0" />
    <limit effort="1000" velocity="100" />
    <origin rpy="0 0 0" xyz="-0.1095 0.0 0" />
  </joint>

  <joint name="torso_r_leg" type="continuous">
    <parent link="torso" />
    <child link="r_leg" />
    <axis xyz="1 0 0" />
   <limit effort="1000" velocity="100" />
   <origin rpy="0 0 0" xyz="0.1095 0.0 0" />
  </joint>

</robot>