<robot name="tumble">

  <material name="white">
    <color rgba="1 1 1 1" />
  </material>

  <material name="black">
    <color rgba="0.2 0.2 0.2 1" />
  </material>

  <link name="torso">
    <visual>
      <geometry>
        <box size=" 0.21176079912771648 0.14855717368538562 0.08530403715561836" />
      </geometry>
      <origin rpy="0 0 0" xyz="0 0.0 0" />
      <material name="white" />
    </visual>
    <collision>
      <geometry>
        <box size=" 0.21176079912771648 0.14855717368538562 0.08530403715561836" />
      </geometry>
      <origin rpy="0 0 0" xyz="0 0.0 0" />
    </collision>
    <inertial>
      <mass value=" 0.6904669475477758" />
      <inertia ixx="0.01160159223458898" ixy="0.004949844510930526" ixz="0.002085706971739552" iyy="0.006548491489415908" iyz="0.0030962223914061497" izz="0.014265035640568122" />
      <origin rpy="0 0 0" xyz="0 0.0 0" />
    </inertial>
  </link>

  <link name="l_leg">
    <visual>
      <geometry>
        <box size=" 0.1287283794051479 0.0031035488094477036 0.007781710231702018" />
      </geometry>
      <origin rpy="0 1.5707963 0" xyz="0 0.0 0.064" />
      <material name="green" />
    </visual>
    <collision>
      <geometry>
        <box size=" 0.1287283794051479 0.0031035488094477036 0.007781710231702018" />
      </geometry>
      <origin rpy="0 1.5707963 0" xyz="0 0.0 0.064" />
      <contact_coefficients mu=" 0.7315048203307493" />
    </collision>
    <inertial>
      <mass value=" 0.0038593609350061056" />
      <inertia ixx="1.983776471573853e-05" ixy="3.6536468639880486e-07" ixz="2.1002962990549578e-08" iyy="1.0416341755304972e-07" iyz="1.0154586983114986e-06" izz="2.1247892411821302e-05" />
      <origin rpy="0 1.5707963 0" xyz="0 0.0 0.064" />
    </inertial>
  </link>

  <link name="r_leg">
    <visual>
      <geometry>
        <box size=" 0.1424777653812807 0.0027632278218002893 0.007812518331542284" />
      </geometry>
      <origin rpy="0 1.5707963 0" xyz="0 0.0 0.064" />
      <material name="black" />
    </visual>
    <collision>
      <geometry>
        <box size=" 0.1424777653812807 0.0027632278218002893 0.007812518331542284" />
      </geometry>
      <origin rpy="0 1.5707963 0" xyz="0 0.0 0.064" />
      <contact_coefficients mu=" 0.7740888515789492" />
    </collision>
    <inertial>
      <mass value=" 0.003823074545607539" />
      <inertia ixx="2.319422869601796e-05" ixy="4.027518151170674e-07" ixz="2.4280986555590198e-08" iyy="1.0803044360755679e-07" iyz="9.998680235808972e-07" izz="2.0270761510470104e-05" />
      <origin rpy="0 1.5707963 0" xyz="0 0.0 0.064" />
    </inertial>
  </link>

  <joint name="torso_l_leg" type="continuous">
    <parent link="torso" />
    <child link="l_leg" />
    <axis xyz="-1 0 0" />
    <limit effort="1000" velocity="100" />
    <origin rpy="0 0 0" xyz="-0.1095 0.0 0" />
  </joint>

  <joint name="torso_r_leg" type="continuous">
    <parent link="torso" />
    <child link="r_leg" />
    <axis xyz="1 0 0" />
   <limit effort="1000" velocity="100" />
   <origin rpy="0 0 0" xyz="0.1095 0.0 0" />
  </joint>

</robot>