<robot name="tumble">

  <material name="white">
    <color rgba="1 1 1 1" />
  </material>

  <material name="black">
    <color rgba="0.2 0.2 0.2 1" />
  </material>

  <link name="torso">
    <visual>
      <geometry>
        <box size=" 0.2013517322528098 0.14607824021983182 0.07560185949992065" />
      </geometry>
      <origin rpy="0 0 0" xyz="0 0.0 0" />
      <material name="white" />
    </visual>
    <collision>
      <geometry>
        <box size=" 0.2013517322528098 0.14607824021983182 0.07560185949992065" />
      </geometry>
      <origin rpy="0 0 0" xyz="0 0.0 0" />
    </collision>
    <inertial>
      <mass value=" 0.6650633227267861" />
      <inertia ixx="0.01089447939714336" ixy="0.004965978197982195" ixz="0.0019288145476167291" iyy="0.005966753870367713" iyz="0.002934890177576248" izz="0.014355490753284366" />
      <origin rpy="0 0 0" xyz="0 0.0 0" />
    </inertial>
  </link>

  <link name="l_leg">
    <visual>
      <geometry>
        <box size=" 0.12876547012424103 0.002992446181452855 0.008058997835967831" />
      </geometry>
      <origin rpy="0 1.5707963 0" xyz="0 0.0 0.064" />
      <material name="green" />
    </visual>
    <collision>
      <geometry>
        <box size=" 0.12876547012424103 0.002992446181452855 0.008058997835967831" />
      </geometry>
      <origin rpy="0 1.5707963 0" xyz="0 0.0 0.064" />
      <contact_coefficients mu=" 0.7856455825186992" />
    </collision>
    <inertial>
      <mass value=" 0.004290182103201311" />
      <inertia ixx="2.3169100815450787e-05" ixy="3.975621977746828e-07" ixz="2.4063419432305817e-08" iyy="9.186243009604769e-08" iyz="1.0917334967197326e-06" izz="1.9718489145425248e-05" />
      <origin rpy="0 1.5707963 0" xyz="0 0.0 0.064" />
    </inertial>
  </link>

  <link name="r_leg">
    <visual>
      <geometry>
        <box size=" 0.12392708392784388 0.0030465996291311774 0.00730710730848076" />
      </geometry>
      <origin rpy="0 1.5707963 0" xyz="0 0.0 0.064" />
      <material name="black" />
    </visual>
    <collision>
      <geometry>
        <box size=" 0.12392708392784388 0.0030465996291311774 0.00730710730848076" />
      </geometry>
      <origin rpy="0 1.5707963 0" xyz="0 0.0 0.064" />
      <contact_coefficients mu=" 0.8178760348034366" />
    </collision>
    <inertial>
      <mass value=" 0.004260279406077649" />
      <inertia ixx="2.284833428540216e-05" ixy="3.927609514904548e-07" ixz="2.530183859114221e-08" iyy="9.397586921871059e-08" iyz="1.0097039936348046e-06" izz="2.17436594936638e-05" />
      <origin rpy="0 1.5707963 0" xyz="0 0.0 0.064" />
    </inertial>
  </link>

  <joint name="torso_l_leg" type="continuous">
    <parent link="torso" />
    <child link="l_leg" />
    <axis xyz="-1 0 0" />
    <limit effort="1000" velocity="100" />
    <origin rpy="0 0 0" xyz="-0.1095 0.0 0" />
  </joint>

  <joint name="torso_r_leg" type="continuous">
    <parent link="torso" />
    <child link="r_leg" />
    <axis xyz="1 0 0" />
   <limit effort="1000" velocity="100" />
   <origin rpy="0 0 0" xyz="0.1095 0.0 0" />
  </joint>

</robot>