<robot name="tumble">

  <material name="white">
    <color rgba="1 1 1 1" />
  </material>

  <material name="black">
    <color rgba="0.2 0.2 0.2 1" />
  </material>

  <link name="torso">
    <visual>
      <geometry>
        <box size=" 0.1965329715330952 0.1393285697742651 0.08780025737304072" />
      </geometry>
      <origin rpy="0 0 0" xyz="0 0.0 0" />
      <material name="white" />
    </visual>
    <collision>
      <geometry>
        <box size=" 0.1965329715330952 0.1393285697742651 0.08780025737304072" />
      </geometry>
      <origin rpy="0 0 0" xyz="0 0.0 0" />
    </collision>
    <inertial>
      <mass value=" 0.582306464220108" />
      <inertia ixx="0.011457244502708117" ixy="0.004928144917357609" ixz="0.002048563613863144" iyy="0.006083320273446649" iyz="0.0027534840448597154" izz="0.013073738229676689" />
      <origin rpy="0 0 0" xyz="0 0.0 0" />
    </inertial>
  </link>

  <link name="l_leg">
    <visual>
      <geometry>
        <box size=" 0.12560585912791178 0.0029324809710593964 0.007895184597464886" />
      </geometry>
      <origin rpy="0 1.5707963 0" xyz="0 0.0 0.064" />
      <material name="green" />
    </visual>
    <collision>
      <geometry>
        <box size=" 0.12560585912791178 0.0029324809710593964 0.007895184597464886" />
      </geometry>
      <origin rpy="0 1.5707963 0" xyz="0 0.0 0.064" />
      <contact_coefficients mu=" 0.8295602997022474" />
    </collision>
    <inertial>
      <mass value=" 0.004092211158311652" />
      <inertia ixx="2.1997213548323274e-05" ixy="3.745732011657077e-07" ixz="2.4015832606641176e-08" iyy="9.49399334811214e-08" iyz="1.0484540856623946e-06" izz="2.0525844659623594e-05" />
      <origin rpy="0 1.5707963 0" xyz="0 0.0 0.064" />
    </inertial>
  </link>

  <link name="r_leg">
    <visual>
      <geometry>
        <box size=" 0.12877850361451312 0.0029015071456413607 0.008822521276230583" />
      </geometry>
      <origin rpy="0 1.5707963 0" xyz="0 0.0 0.064" />
      <material name="black" />
    </visual>
    <collision>
      <geometry>
        <box size=" 0.12877850361451312 0.0029015071456413607 0.008822521276230583" />
      </geometry>
      <origin rpy="0 1.5707963 0" xyz="0 0.0 0.064" />
      <contact_coefficients mu=" 0.838754311816707" />
    </collision>
    <inertial>
      <mass value=" 0.003811071767972682" />
      <inertia ixx="2.0913158730782287e-05" ixy="3.723929029938838e-07" ixz="2.3318930968051105e-08" iyy="1.0351927919955415e-07" iyz="9.814550678845364e-07" izz="2.1327656661861464e-05" />
      <origin rpy="0 1.5707963 0" xyz="0 0.0 0.064" />
    </inertial>
  </link>

  <joint name="torso_l_leg" type="continuous">
    <parent link="torso" />
    <child link="l_leg" />
    <axis xyz="-1 0 0" />
    <limit effort="1000" velocity="100" />
    <origin rpy="0 0 0" xyz="-0.1095 0.0 0" />
  </joint>

  <joint name="torso_r_leg" type="continuous">
    <parent link="torso" />
    <child link="r_leg" />
    <axis xyz="1 0 0" />
   <limit effort="1000" velocity="100" />
   <origin rpy="0 0 0" xyz="0.1095 0.0 0" />
  </joint>

</robot>