<robot name="tumble">

  <material name="white">
    <color rgba="1 1 1 1" />
  </material>

  <material name="black">
    <color rgba="0.2 0.2 0.2 1" />
  </material>

  <link name="torso">
    <visual>
      <geometry>
        <box size=" 0.19410158632473573 0.1274466224780315 0.07996369997185833" />
      </geometry>
      <origin rpy="0 0 0" xyz="0 0.0 0" />
      <material name="white" />
    </visual>
    <collision>
      <geometry>
        <box size=" 0.19410158632473573 0.1274466224780315 0.07996369997185833" />
      </geometry>
      <origin rpy="0 0 0" xyz="0 0.0 0" />
    </collision>
    <inertial>
      <mass value=" 0.7025769416961459" />
      <inertia ixx="0.011654212862517024" ixy="0.004670515091251304" ixz="0.0020575508091653363" iyy="0.0060199346325316315" iyz="0.002875903433408096" izz="0.014769740401834803" />
      <origin rpy="0 0 0" xyz="0 0.0 0" />
    </inertial>
  </link>

  <link name="l_leg">
    <visual>
      <geometry>
        <box size=" 0.13125845072710113 0.00283364945814466 0.008492797624720907" />
      </geometry>
      <origin rpy="0 1.5707963 0" xyz="0 0.0 0.064" />
      <material name="green" />
    </visual>
    <collision>
      <geometry>
        <box size=" 0.13125845072710113 0.00283364945814466 0.008492797624720907" />
      </geometry>
      <origin rpy="0 1.5707963 0" xyz="0 0.0 0.064" />
      <contact_coefficients mu=" 0.7776818714074232" />
    </collision>
    <inertial>
      <mass value=" 0.0038359235544950885" />
      <inertia ixx="2.207652479281968e-05" ixy="3.6696228061289643e-07" ixz="2.2871764312050745e-08" iyy="1.0415361917211195e-07" iyz="1.0306272133302351e-06" izz="2.0664216583680217e-05" />
      <origin rpy="0 1.5707963 0" xyz="0 0.0 0.064" />
    </inertial>
  </link>

  <link name="r_leg">
    <visual>
      <geometry>
        <box size=" 0.12166773269287333 0.002989163056008693 0.008342181185234597" />
      </geometry>
      <origin rpy="0 1.5707963 0" xyz="0 0.0 0.064" />
      <material name="black" />
    </visual>
    <collision>
      <geometry>
        <box size=" 0.12166773269287333 0.002989163056008693 0.008342181185234597" />
      </geometry>
      <origin rpy="0 1.5707963 0" xyz="0 0.0 0.064" />
      <contact_coefficients mu=" 0.7899779877770824" />
    </collision>
    <inertial>
      <mass value=" 0.003982290364724499" />
      <inertia ixx="2.3184564730785647e-05" ixy="3.7068793462383184e-07" ixz="2.406253167122276e-08" iyy="9.477624424947885e-08" iyz="1.0598607527499693e-06" izz="2.1460561539380297e-05" />
      <origin rpy="0 1.5707963 0" xyz="0 0.0 0.064" />
    </inertial>
  </link>

  <joint name="torso_l_leg" type="continuous">
    <parent link="torso" />
    <child link="l_leg" />
    <axis xyz="-1 0 0" />
    <limit effort="1000" velocity="100" />
    <origin rpy="0 0 0" xyz="-0.1095 0.0 0" />
  </joint>

  <joint name="torso_r_leg" type="continuous">
    <parent link="torso" />
    <child link="r_leg" />
    <axis xyz="1 0 0" />
   <limit effort="1000" velocity="100" />
   <origin rpy="0 0 0" xyz="0.1095 0.0 0" />
  </joint>

</robot>