<robot name="tumble">

  <material name="white">
    <color rgba="1 1 1 1" />
  </material>

  <material name="black">
    <color rgba="0.2 0.2 0.2 1" />
  </material>

  <link name="torso">
    <visual>
      <geometry>
        <box size=" 0.21027768806944325 0.13507030319575247 0.08408501654737784" />
      </geometry>
      <origin rpy="0 0 0" xyz="0 0.0 0" />
      <material name="white" />
    </visual>
    <collision>
      <geometry>
        <box size=" 0.21027768806944325 0.13507030319575247 0.08408501654737784" />
      </geometry>
      <origin rpy="0 0 0" xyz="0 0.0 0" />
    </collision>
    <inertial>
      <mass value=" 0.7500283853261341" />
      <inertia ixx="0.01127158571648284" ixy="0.0048001915372506134" ixz="0.002199379528016649" iyy="0.006213616914120281" iyz="0.0029750751867237465" izz="0.01352366724268759" />
      <origin rpy="0 0 0" xyz="0 0.0 0" />
    </inertial>
  </link>

  <link name="l_leg">
    <visual>
      <geometry>
        <box size=" 0.12693438072730476 0.0028514537559152188 0.0074947791497689455" />
      </geometry>
      <origin rpy="0 1.5707963 0" xyz="0 0.0 0.064" />
      <material name="green" />
    </visual>
    <collision>
      <geometry>
        <box size=" 0.12693438072730476 0.0028514537559152188 0.0074947791497689455" />
      </geometry>
      <origin rpy="0 1.5707963 0" xyz="0 0.0 0.064" />
      <contact_coefficients mu=" 0.8041852153890018" />
    </collision>
    <inertial>
      <mass value=" 0.0038881489750844126" />
      <inertia ixx="2.1443944998483753e-05" ixy="4.0915395615444427e-07" ixz="2.248033835145551e-08" iyy="9.65003964629341e-08" iyz="1.0333444077144337e-06" izz="2.181458606561132e-05" />
      <origin rpy="0 1.5707963 0" xyz="0 0.0 0.064" />
    </inertial>
  </link>

  <link name="r_leg">
    <visual>
      <geometry>
        <box size=" 0.12291210191770903 0.0031057229678971925 0.008921413813443321" />
      </geometry>
      <origin rpy="0 1.5707963 0" xyz="0 0.0 0.064" />
      <material name="black" />
    </visual>
    <collision>
      <geometry>
        <box size=" 0.12291210191770903 0.0031057229678971925 0.008921413813443321" />
      </geometry>
      <origin rpy="0 1.5707963 0" xyz="0 0.0 0.064" />
      <contact_coefficients mu=" 0.7950810382321621" />
    </collision>
    <inertial>
      <mass value=" 0.003965746379128522" />
      <inertia ixx="2.221515588786775e-05" ixy="3.715968830255999e-07" ixz="2.291341481766543e-08" iyy="8.896264863840167e-08" iyz="9.489979268269883e-07" izz="2.221893425520206e-05" />
      <origin rpy="0 1.5707963 0" xyz="0 0.0 0.064" />
    </inertial>
  </link>

  <joint name="torso_l_leg" type="continuous">
    <parent link="torso" />
    <child link="l_leg" />
    <axis xyz="-1 0 0" />
    <limit effort="1000" velocity="100" />
    <origin rpy="0 0 0" xyz="-0.1095 0.0 0" />
  </joint>

  <joint name="torso_r_leg" type="continuous">
    <parent link="torso" />
    <child link="r_leg" />
    <axis xyz="1 0 0" />
   <limit effort="1000" velocity="100" />
   <origin rpy="0 0 0" xyz="0.1095 0.0 0" />
  </joint>

</robot>